<mujoco model="arm_2link">
  <compiler angle="degree" coordinate="local" />
  <option timestep="0.01" gravity="0 0 -9.81"/>
  <worldbody>
    <body name="base" pos="0 0 0.02">
      <geom type="cylinder" size="0.03 0.02" rgba="0.4 0.4 0.4 1"/>
      <body name="link1" pos="0 0 0">
        <joint name="joint1" type="hinge" axis="0 0 1" range="-90 90" damping="0.05"/>
        <geom type="capsule" fromto="0 0 0 0.2 0 0" size="0.02" rgba="0.2 0.6 0.9 1"/>
        <body name="link2" pos="0.2 0 0">
          <joint name="joint2" type="hinge" axis="0 0 1" range="-90 90" damping="0.05"/>
          <geom type="capsule" fromto="0 0 0 0.2 0 0" size="0.02" rgba="0.2 0.9 0.4 1"/>
          <site name="ee_site" pos="0.2 0 0" size="0.02" rgba="1 0 0 1"/>
        </body>
      </body>
    </body>
  </worldbody>
  <actuator>
    <motor name="motor1" joint="joint1" ctrlrange="-1 1" gear="1"/>
    <motor name="motor2" joint="joint2" ctrlrange="-1 1" gear="1"/>
  </actuator>
  <keyframe>
    <key name="home" qpos="0 0" ctrl="0 0"/>
  </keyframe>
</mujoco>
