<!-- assets/ainex/ainex_physics.xml -->
<mujoco model="ainex">
  <compiler angle="radian"/>

  <option timestep="0.002" gravity="0 0 -9.81" iterations="100" tolerance="1e-8" solver="Newton"/>

  <default>
    <joint damping="0.05" armature="0.02" limited="true"/>

    <!-- Contact defaults
         - condim=6 enables torsional + rolling friction (helps feet stop "ice skating")
         - friction is (sliding torsional rolling)
         - slightly softer contact helps stability during standing/settling -->
    <geom friction="1.2 0.03 0.003" solref="0.03 1" solimp="0.90 0.95 0.001" condim="6"/>

    <!-- Foot-specific contact tuning (higher sliding friction, still stable) -->
    <default class="foot">
      <geom friction="2.2 0.05 0.005" condim="6"
            solref="0.02 1" solimp="0.90 0.95 0.001"/>
    </default>

    <!-- Position actuator safety defaults
         NOTE: per-actuator forcerange overrides below are what really fix playback -->
    <position ctrllimited="true" ctrlrange="-2.09 2.09" forcelimited="true" forcerange="-600 600"/>
  </default>

  <asset>
    <mesh name="body_link" content_type="model/stl" file="meshes/body_link.STL"/>
    <mesh name="r_hip_yaw_link" content_type="model/stl" file="meshes/r_hip_yaw_link.STL"/>
    <mesh name="r_hip_roll_link" content_type="model/stl" file="meshes/r_hip_roll_link.STL"/>
    <mesh name="r_hip_pitch_link" content_type="model/stl" file="meshes/r_hip_pitch_link.STL"/>
    <mesh name="r_knee_link" content_type="model/stl" file="meshes/r_knee_link.STL"/>
    <mesh name="r_ank_pitch_link" content_type="model/stl" file="meshes/r_ank_pitch_link.STL"/>
    <mesh name="r_ank_roll_link" content_type="model/stl" file="meshes/r_ank_roll_link.STL"/>
    <mesh name="l_hip_yaw_link" content_type="model/stl" file="meshes/l_hip_yaw_link.STL"/>
    <mesh name="l_hip_roll_link" content_type="model/stl" file="meshes/l_hip_roll_link.STL"/>
    <mesh name="l_hip_pitch_link" content_type="model/stl" file="meshes/l_hip_pitch_link.STL"/>
    <mesh name="l_knee_link" content_type="model/stl" file="meshes/l_knee_link.STL"/>
    <mesh name="l_ank_pitch_link" content_type="model/stl" file="meshes/l_ank_pitch_link.STL"/>
    <mesh name="l_ank_roll_link" content_type="model/stl" file="meshes/l_ank_roll_link.STL"/>
    <mesh name="head_pan_link" content_type="model/stl" file="meshes/head_pan_link.STL"/>
    <mesh name="head_tilt_link" content_type="model/stl" file="meshes/head_tilt_link.STL"/>
    <mesh name="r_sho_pitch_link" content_type="model/stl" file="meshes/r_sho_pitch_link.STL"/>
    <mesh name="r_sho_roll_link" content_type="model/stl" file="meshes/r_sho_roll_link.STL"/>
    <mesh name="r_el_pitch_link" content_type="model/stl" file="meshes/r_el_pitch_link.STL"/>
    <mesh name="r_el_yaw_link" content_type="model/stl" file="meshes/r_el_yaw_link.STL"/>
    <mesh name="r_gripper_link" content_type="model/stl" file="meshes/r_gripper_link.STL"/>
    <mesh name="l_sho_pitch_link" content_type="model/stl" file="meshes/l_sho_pitch_link.STL"/>
    <mesh name="l_sho_roll_link" content_type="model/stl" file="meshes/l_sho_roll_link.STL"/>
    <mesh name="l_el_pitch_link" content_type="model/stl" file="meshes/l_el_pitch_link.STL"/>
    <mesh name="l_el_yaw_link" content_type="model/stl" file="meshes/l_el_yaw_link.STL"/>
    <mesh name="l_gripper_link" content_type="model/stl" file="meshes/l_gripper_link.STL"/>
  </asset>

  <contact>
    <!-- Adjacent leg exclusions (right) -->
    <exclude body1="r_hip_yaw_link"   body2="r_hip_roll_link"/>
    <exclude body1="r_hip_roll_link"  body2="r_hip_pitch_link"/>
    <exclude body1="r_hip_pitch_link" body2="r_knee_link"/>
    <exclude body1="r_knee_link"      body2="r_ank_pitch_link"/>
    <exclude body1="r_ank_pitch_link" body2="r_ank_roll_link"/>

    <!-- Adjacent leg exclusions (left) -->
    <exclude body1="l_hip_yaw_link"   body2="l_hip_roll_link"/>
    <exclude body1="l_hip_roll_link"  body2="l_hip_pitch_link"/>
    <exclude body1="l_hip_pitch_link" body2="l_knee_link"/>
    <exclude body1="l_knee_link"      body2="l_ank_pitch_link"/>
    <exclude body1="l_ank_pitch_link" body2="l_ank_roll_link"/>

    <!-- Feet should not collide with their own chain -->
    <exclude body1="r_ank_roll_link" body2="r_knee_link"/>
    <exclude body1="r_ank_roll_link" body2="r_hip_pitch_link"/>
    <exclude body1="r_ank_roll_link" body2="r_hip_roll_link"/>
    <exclude body1="r_ank_roll_link" body2="r_hip_yaw_link"/>

    <exclude body1="l_ank_roll_link" body2="l_knee_link"/>
    <exclude body1="l_ank_roll_link" body2="l_hip_pitch_link"/>
    <exclude body1="l_ank_roll_link" body2="l_hip_roll_link"/>
    <exclude body1="l_ank_roll_link" body2="l_hip_yaw_link"/>

    <!-- Torso vs upper legs (often always close) -->
    <exclude body1="torso" body2="r_hip_yaw_link"/>
    <exclude body1="torso" body2="r_hip_roll_link"/>
    <exclude body1="torso" body2="r_hip_pitch_link"/>
    <exclude body1="torso" body2="l_hip_yaw_link"/>
    <exclude body1="torso" body2="l_hip_roll_link"/>
    <exclude body1="torso" body2="l_hip_pitch_link"/>

    <!-- Adjacent arm exclusions -->
    <exclude body1="r_sho_pitch_link" body2="r_sho_roll_link"/>
    <exclude body1="r_sho_roll_link"  body2="r_el_pitch_link"/>
    <exclude body1="r_el_pitch_link"  body2="r_el_yaw_link"/>
    <exclude body1="r_el_yaw_link"    body2="r_gripper_link"/>

    <exclude body1="l_sho_pitch_link" body2="l_sho_roll_link"/>
    <exclude body1="l_sho_roll_link"  body2="l_el_pitch_link"/>
    <exclude body1="l_el_pitch_link"  body2="l_el_yaw_link"/>
    <exclude body1="l_el_yaw_link"    body2="l_gripper_link"/>

    <!-- Arms vs torso (prevents constant chatter) -->
    <exclude body1="torso" body2="r_sho_pitch_link"/>
    <exclude body1="torso" body2="r_sho_roll_link"/>
    <exclude body1="torso" body2="l_sho_pitch_link"/>
    <exclude body1="torso" body2="l_sho_roll_link"/>

    <!-- Foot contacts exclusions -->
    <exclude body1="r_ank_roll_link" body2="l_ank_roll_link"/>
  </contact>

  <worldbody>
    <geom name="ref_line_x" type="box" pos="1 0 0.001" size="1 0.002 0.001" rgba="0.2 0.2 0.2 1" contype="0" conaffinity="0"/>
    <geom name="ref_line_y" type="box" pos="0 1 0.001" size="0.002 1 0.001" rgba="0.2 0.2 0.2 1" contype="0" conaffinity="0"/>

    <light name="key" directional="true" pos="0 0 3" dir="0 0 -1" diffuse="2 2 2" specular="1 1 1"/>
    <light name="fill" directional="false" pos="2 2 2" diffuse="1 1 1" specular="0.5 0.5 0.5"/>
    <light name="rim" directional="true" pos="0 0 3" dir="-1 -1 -1" diffuse="0.8 0.8 0.8" specular="0.2 0.2 0.2"/>

    <!-- Slightly higher floor friction; condim=6 matches default -->
    <geom name="floor" type="plane" pos="0 0 0" size="5 5 0.1" rgba="0.9 0.9 0.9 1"
          friction="1.1 0.35 0.35" condim="6" contype="1" conaffinity="1"/>

    <body name="torso" pos="0 0 0.05">
      <freejoint/>

      <!-- Visual mesh only -->
      <geom type="mesh" contype="0" conaffinity="0" rgba="0.1 0.1 0.1 1" mesh="body_link"/>

      <!-- Torso collision model (simple) -->
      <geom name="torso_col" type="box" pos="0 0 0.06" size="0.045 0.030 0.060"
            rgba="0 0 0 0" contype="1" conaffinity="1"/>

      <!-- Electronics ballast: approximate Pi + battery mass in back cavity -->
      <body name="electronics_ballast" pos="-0.030 0 0.070">
        <!-- Start with ~0.18 kg total; tune later -->
        <inertial pos="0 0 0" mass="0.18" diaginertia="0.00012 0.00012 0.00012"/>
        <!-- Visual/placeholder shape; non-colliding -->
        <geom name="electronics_ballast_geom"
              type="box" size="0.040 0.025 0.020"
              rgba="0.2 0.2 0.2 0.2"
              contype="0" conaffinity="0"/>
      </body>

      <!-- RIGHT LEG -->
      <body name="r_hip_yaw_link" pos="0 -0.029 0">
        <inertial pos="-3.08089e-05 0.00125727 -0.00137107" quat="0.685451 0.035864 -0.0116524 0.727142" mass="0.032" diaginertia="2.27792e-05 1.75538e-05 8.97703e-06"/>
        <joint name="r_hip_yaw" pos="0 0 0" axis="0 0 -1" range="-2.09 2.09" damping="0.02"/>
        <geom type="mesh" contype="0" conaffinity="0" rgba="0.1 0.1 0.1 1" mesh="r_hip_yaw_link"/>

        <body name="r_hip_roll_link" pos="-0.01955 0 -0.0255">
          <inertial pos="0.0013624 -0.000566876 -0.0134187" quat="0.498207 0.491474 0.501276 0.508887" mass="0.12" diaginertia="7.31184e-05 6.05065e-05 2.91551e-05"/>
          <joint name="r_hip_roll" pos="0 0 0" axis="-1 0 0" range="-2.09 2.09" damping="0.02"/>
          <geom type="mesh" contype="0" conaffinity="0" rgba="0.1 0.1 0.1 1" mesh="r_hip_roll_link"/>

          <body name="r_hip_pitch_link" pos="0.0190366 -0.02 0">
            <inertial pos="0.0135944 0.0193812 -0.0727054" quat="0.738938 0.0427036 0.0407745 0.671181" mass="0.1065" diaginertia="0.000112942 0.000111046 4.06518e-05"/>
            <joint name="r_hip_pitch" pos="0 0 0" axis="0 -1 0" range="-2.09 2.09" damping="0.02"/>
            <geom type="mesh" contype="0" conaffinity="0" rgba="0.1 0.1 0.1 1" mesh="r_hip_pitch_link"/>

            <!-- Thigh collision (right) -->
            <geom name="r_thigh_col" type="capsule" fromto="0 0 0  0.00 0.00 -0.085" size="0.018"
                  rgba="0 0 0 0" contype="1" conaffinity="1"/>

            <body name="r_knee_link" pos="-0.000372039 5e-05 -0.0968862">
              <geom name="r_shin_col" type="capsule" fromto="0 0 0  0 0 -0.09" size="0.018"
                    rgba="0 0 0 0" contype="1" conaffinity="1"/>

              <inertial pos="0.00334266 0.0196474 -0.0425049" quat="0.999535 -0.000104839 -0.0304236 0.0019934" mass="0.045" diaginertia="6.75039e-05 5.49998e-05 2.05563e-05"/>
              <joint name="r_knee" pos="0 0 0" axis="0 -1 0" range="-2.09 2.09" damping="0.02"/>
              <geom type="mesh" contype="0" conaffinity="0" rgba="0.1 0.1 0.1 1" mesh="r_knee_link"/>

              <body name="r_ank_pitch_link" pos="0.00103699 0 -0.0890766">
                <inertial pos="-0.017544 0.0195632 0.0134182" quat="0.489309 0.496862 0.510389 0.503197" mass="0.12" diaginertia="7.36835e-05 6.10769e-05 2.91596e-05"/>
                <joint name="r_ank_pitch" pos="0 0 0" axis="0 1 0" range="-2.09 2.09" damping="0.02"/>
                <geom type="mesh" contype="0" conaffinity="0" rgba="0.1 0.1 0.1 1" mesh="r_ank_pitch_link"/>

                <body name="r_ank_roll_link" pos="-0.0190366 0.02 0">
                  <inertial pos="0.0285085 -0.0128729 -0.017671" quat="0.0257514 0.696659 0.0389182 0.715883" mass="0.0675" diaginertia="0.000126012 9.21991e-05 4.20891e-05"/>
                  <joint name="r_ank_roll" pos="0 0 0" axis="1 0 0" range="-2.09 2.09" damping="0.02"/>
                  <geom type="mesh" contype="0" conaffinity="0" rgba="0.1 0.1 0.1 1" mesh="r_ank_roll_link"/>

                  <!-- Foot contact:
                       Use two boxes (heel + toe) to guarantee full ground support even if the toe sticks out.
                       Adjust X positions/sizes if your mesh footprint differs. -->
                  <geom class="foot" name="r_heel_col" type="box"
                        pos="-0.012 -0.03 -0.018" size="0.020 0.04 0.01" margin="0.002"
                        rgba="0 0 0 0" contype="1" conaffinity="1"/>
                  <geom class="foot" name="r_toe_col" type="box"
                        pos="0.08 -0.03 -0.018" size="0.07 0.04 0.01" margin="0.002"
                        rgba="0 0 0 0" contype="1" conaffinity="1"/>
                </body>
              </body>
            </body>
          </body>
        </body>
      </body>

      <!-- LEFT LEG -->
      <body name="l_hip_yaw_link" pos="0 0.029 0">
        <inertial pos="-3.11406e-05 -0.00125722 -0.0013713" quat="0.727661 -0.0116933 0.0358264 0.684901" mass="0.032" diaginertia="2.27801e-05 1.75528e-05 8.97707e-06"/>
        <joint name="l_hip_yaw" pos="0 0 0" axis="0 0 -1" range="-2.09 2.09" damping="0.02"/>
        <geom type="mesh" contype="0" conaffinity="0" rgba="0.1 0.1 0.1 1" mesh="l_hip_yaw_link"/>

        <body name="l_hip_roll_link" pos="-0.01955 0 -0.0255">
          <inertial pos="0.00136239 0.000566861 -0.0134187" quat="0.508887 0.501276 0.491474 0.498207" mass="0.12" diaginertia="7.31184e-05 6.05065e-05 2.91551e-05"/>
          <joint name="l_hip_roll" pos="0 0 0" axis="-1 0 0" range="-2.09 2.09" damping="0.02"/>
          <geom type="mesh" contype="0" conaffinity="0" rgba="0.1 0.1 0.1 1" mesh="l_hip_roll_link"/>

          <body name="l_hip_pitch_link" pos="0.019037 0.02 0">
            <inertial pos="0.0135944 -0.0193812 -0.0727051" quat="0.671181 0.0407745 0.0427036 0.738938" mass="0.1065" diaginertia="0.000112942 0.000111046 4.06518e-05"/>
            <joint name="l_hip_pitch" pos="0 0 0" axis="0 1 0" range="-2.09 2.09" damping="0.02"/>
            <geom type="mesh" contype="0" conaffinity="0" rgba="0.1 0.1 0.1 1" mesh="l_hip_pitch_link"/>

            <!-- Thigh collision (left) -->
            <geom name="l_thigh_col" type="capsule" fromto="0 0 0  0.00 0.00 -0.085" size="0.018"
                  rgba="0 0 0 0" contype="1" conaffinity="1"/>

            <body name="l_knee_link" pos="-0.00037204 -5e-05 -0.096886">
              <geom name="l_shin_col" type="capsule" fromto="0 0 0  0 0 -0.09" size="0.018"
                    rgba="0 0 0 0" contype="1" conaffinity="1"/>

              <inertial pos="0.00334256 -0.0196465 -0.0425053" quat="0.999536 8.38713e-05 -0.0304236 -0.00159474" mass="0.045" diaginertia="6.75038e-05 5.49999e-05 2.05563e-05"/>
              <joint name="l_knee" pos="0 0 0" axis="0 1 0" range="-2.09 2.09" damping="0.02"/>
              <geom type="mesh" contype="0" conaffinity="0" rgba="0.1 0.1 0.1 1" mesh="l_knee_link"/>

              <body name="l_ank_pitch_link" pos="0.001037 0 -0.089077">
                <inertial pos="-0.017544 -0.0195632 0.0134182" quat="0.503197 0.510389 0.496862 0.489309" mass="0.12" diaginertia="7.36835e-05 6.10769e-05 2.91596e-05"/>
                <joint name="l_ank_pitch" pos="0 0 0" axis="0 -1 0" range="-2.09 2.09" damping="0.02"/>
                <geom type="mesh" contype="0" conaffinity="0" rgba="0.1 0.1 0.1 1" mesh="l_ank_pitch_link"/>

                <body name="l_ank_roll_link" pos="-0.019037 -0.02 0">
                  <inertial pos="0.028508 0.012873 -0.017671" quat="-0.0257514 0.696659 -0.0389182 0.715883" mass="0.0675" diaginertia="0.000126012 9.21991e-05 4.20891e-05"/>
                  <joint name="l_ank_roll" pos="0 0 0" axis="1 0 0" range="-2.09 2.09" damping="0.02"/>
                  <geom type="mesh" contype="0" conaffinity="0" rgba="0.1 0.1 0.1 1" mesh="l_ank_roll_link"/>

                  <!-- Foot contact (heel + toe) -->
                  <geom class="foot" name="l_heel_col" type="box"
                        pos="-0.012 0.03 -0.018" size="0.020 0.04 0.01" margin="0.002"
                        rgba="0 0 0 0" contype="1" conaffinity="1"/>
                  <geom class="foot" name="l_toe_col" type="box"
                        pos="0.08 0.03 -0.018" size="0.07 0.04 0.01" margin="0.002"
                        rgba="0 0 0 0" contype="1" conaffinity="1"/>
                </body>
              </body>
            </body>
          </body>
        </body>
      </body>

      <!-- HEAD -->
      <body name="head_pan_link" pos="-0.00410029 0 0.1078">
        <inertial pos="0.00549414 0.000156599 0.0141339" quat="0.693159 0.693116 0.139862 -0.139857" mass="0.00767349" diaginertia="2.17841e-06 1.77447e-06 9.86663e-07"/>
        <joint name="head_pan" pos="0 0 0" axis="0 0 -1" range="-2.09 2.09" damping="0.05"/>
        <geom type="mesh" contype="0" conaffinity="0" rgba="0.1 0.1 0.1 1" mesh="head_pan_link"/>
        <body name="head_tilt_link" pos="0.00904595 -0.0185734 0.0281579">
          <inertial pos="0.0113381 0.0189173 0.0221227" quat="0.00744474 0.879474 -0.0114416 0.475751" mass="0.0262249" diaginertia="7.42721e-06 6.32366e-06 5.6713e-06"/>
          <joint name="head_tilt" pos="0 0 0" axis="0 -1 0" range="-2.09 2.09" damping="0.05"/>
          <geom type="mesh" contype="0" conaffinity="0" rgba="0.1 0.1 0.1 1" mesh="head_tilt_link"/>
        </body>
      </body>

      <!-- RIGHT ARM -->
      <body name="r_sho_pitch_link" pos="-5.46274e-05 -0.052491 0.087448">
        <inertial pos="0.000375793 -0.0113307 2.09986e-06" quat="-0.00954592 0.707042 0.00954592 0.707042" mass="0.0128" diaginertia="5.03e-06 3.90135e-06 2.04865e-06"/>
        <joint name="r_sho_pitch" pos="0 0 0" axis="0 -1 0" range="-2.09 2.09" frictionloss="0" damping="0.05"/>
        <geom type="mesh" contype="0" conaffinity="0" rgba="0.1 0.1 0.1 1" mesh="r_sho_pitch_link"/>

        <geom name="r_upperarm_col" type="capsule" fromto="0 0 0  0.00 -0.06 0.00" size="0.015"
              rgba="0 0 0 0" contype="1" conaffinity="1"/>

        <body name="r_sho_roll_link" pos="0.0200035 -0.021506 0">
          <inertial pos="-0.0205038 -0.0278388 -6.10732e-05" quat="0.428351 0.520926 -0.479863 0.561144" mass="0.121" diaginertia="7.5398e-05 7.4522e-05 2.37399e-05"/>
          <joint name="r_sho_roll" pos="0 0 0" axis="1 0 0" range="-2.09 2.09" frictionloss="0" damping="0.05"/>
          <geom type="mesh" contype="0" conaffinity="0" rgba="0.1 0.1 0.1 1" mesh="r_sho_roll_link"/>

          <body name="r_el_pitch_link" pos="-0.0200035 -0.0741099 0">
            <inertial pos="-0.00697553 -0.0128964 0.000205171" quat="0.20604 0.650508 -0.249985 0.686945" mass="0.045" diaginertia="1.05425e-05 8.79567e-06 7.46187e-06"/>
            <joint name="r_el_pitch" pos="0 0 0" axis="0 -1 0" range="-2.09 2.09" frictionloss="0" damping="0.05"/>
            <geom type="mesh" contype="0" conaffinity="0" rgba="0.1 0.1 0.1 1" mesh="r_el_pitch_link"/>

            <geom name="r_forearm_col" type="capsule" fromto="0 0 0  0.00 -0.06 0.00" size="0.013"
                  rgba="0 0 0 0" contype="1" conaffinity="1"/>

            <body name="r_el_yaw_link" pos="0.000397813 -0.0170183 0.0190702">
              <inertial pos="-0.000228559 -0.0572724 -0.0138716" quat="0.66352 0.747563 0.0231725 -0.0188373" mass="0.102" diaginertia="0.000143205 0.000142106 2.94195e-05"/>
              <joint name="r_el_yaw" pos="0 0 0" axis="0 0 1" range="-2.09 2.09" frictionloss="0" damping="0.05"/>
              <geom type="mesh" contype="0" conaffinity="0" rgba="0.1 0.1 0.1 1" mesh="r_el_yaw_link"/>
              <body name="r_gripper_link" pos="0.0198902 -0.0892356 -0.0190702">
                <inertial pos="-0.0193851 -0.00931115 -0.00543048" quat="0.15915 0.685412 0.178235 0.687833" mass="0.0135" diaginertia="6.51914e-06 3.96161e-06 3.27925e-06"/>
                <joint name="r_gripper" pos="0 0 0" axis="1 0 0" range="-2.09 2.09" frictionloss="0" damping="0.05"/>
                <geom type="mesh" contype="0" conaffinity="0" rgba="0.1 0.1 0.1 1" mesh="r_gripper_link"/>
              </body>
            </body>
          </body>
        </body>
      </body>

      <!-- LEFT ARM -->
      <body name="l_sho_pitch_link" pos="-5.4627e-05 0.052491 0.087448">
        <inertial pos="0.000375774 0.0113303 1.96337e-06" quat="0.00954592 0.707042 -0.00954592 0.707042" mass="0.0128" diaginertia="5.03e-06 3.90135e-06 2.04865e-06"/>
        <joint name="l_sho_pitch" pos="0 0 0" axis="0 -1 0" range="-2.09 2.09" frictionloss="0" damping="0.05"/>
        <geom type="mesh" contype="0" conaffinity="0" rgba="0.1 0.1 0.1 1" mesh="l_sho_pitch_link"/>

        <geom name="l_upperarm_col" type="capsule" fromto="0 0 0  0.00 0.06 0.00" size="0.015"
              rgba="0 0 0 0" contype="1" conaffinity="1"/>

        <body name="l_sho_roll_link" pos="0.020003 0.021507 0">
          <inertial pos="-0.020504 0.027838 -6.0431e-05" quat="0.520926 0.428351 -0.561144 0.479863" mass="0.121" diaginertia="7.5398e-05 7.4522e-05 2.37399e-05"/>
          <joint name="l_sho_roll" pos="0 0 0" axis="1 0 0" range="-2.09 2.09" frictionloss="0" damping="0.05"/>
          <geom type="mesh" contype="0" conaffinity="0" rgba="0.1 0.1 0.1 1" mesh="l_sho_roll_link"/>

          <body name="l_el_pitch_link" pos="-0.020003 0.074109 0">
            <inertial pos="-0.0069756 0.012896 0.0002073" quat="-0.20604 0.650508 0.249985 0.686945" mass="0.045" diaginertia="1.05425e-05 8.79567e-06 7.46187e-06"/>
            <joint name="l_el_pitch" pos="0 0 0" axis="0 -1 0" range="-2.09 2.09" frictionloss="0" damping="0.05"/>
            <geom type="mesh" contype="0" conaffinity="0" rgba="0.1 0.1 0.1 1" mesh="l_el_pitch_link"/>

            <geom name="l_forearm_col" type="capsule" fromto="0 0 0  0.00 0.06 0.00" size="0.013"
                  rgba="0 0 0 0" contype="1" conaffinity="1"/>

            <body name="l_el_yaw_link" pos="0.00039506 0.017019 0.019072">
              <inertial pos="-0.00022583 0.0572712 -0.0138703" quat="0.747563 0.66352 0.0188373 -0.0231725" mass="0.102" diaginertia="0.000143205 0.000142106 2.94195e-05"/>
              <joint name="l_el_yaw" pos="0 0 0" axis="0 0 1" range="-2.09 2.09" frictionloss="0" damping="0.05"/>
              <geom type="mesh" contype="0" conaffinity="0" rgba="0.1 0.1 0.1 1" mesh="l_el_yaw_link"/>
              <body name="l_gripper_link" pos="0.019893 0.089232 -0.019072">
                <inertial pos="-0.019384 0.0093137 -0.005426" quat="-0.15915 0.685412 -0.178235 0.687833" mass="0.0135" diaginertia="6.51914e-06 3.96161e-06 3.27925e-06"/>
                <joint name="l_gripper" pos="0 0 0" axis="1 0 0" range="-2.09 2.09" frictionloss="0" damping="0.05"/>
                <geom type="mesh" contype="0" conaffinity="0" rgba="0.1 0.1 0.1 1" mesh="l_gripper_link"/>
              </body>
            </body>
          </body>
        </body>
      </body>

    </body>
  </worldbody>

  <actuator>
    <!-- right leg (higher force; floating base + contacts needs this) -->
    <position name="00_r_hip_yaw"   joint="r_hip_yaw"   kp="28" kv="7" forcerange="-1200 1200"/>
    <position name="01_r_hip_roll"  joint="r_hip_roll"  kp="28" kv="7" forcerange="-1200 1200"/>
    <position name="02_r_hip_pitch" joint="r_hip_pitch" kp="28" kv="7" forcerange="-1200 1200"/>
    <position name="03_r_knee"      joint="r_knee"      kp="28" kv="7" forcerange="-1200 1200"/>
    <position name="04_r_ank_pitch" joint="r_ank_pitch" kp="18" kv="5" forcerange="-140 140"/>
    <position name="05_r_ank_roll"  joint="r_ank_roll"  kp="18" kv="5" forcerange="-140 140"/>

    <!-- left leg -->
    <position name="06_l_hip_yaw"   joint="l_hip_yaw"   kp="28" kv="7" forcerange="-200 200"/>
    <position name="07_l_hip_roll"  joint="l_hip_roll"  kp="28" kv="7" forcerange="-200 200"/>
    <position name="08_l_hip_pitch" joint="l_hip_pitch" kp="28" kv="7" forcerange="-200 200"/>
    <position name="09_l_knee"      joint="l_knee"      kp="28" kv="7" forcerange="-220 220"/>
    <position name="10_l_ank_pitch" joint="l_ank_pitch" kp="18" kv="5" forcerange="-140 140"/>
    <position name="11_l_ank_roll"  joint="l_ank_roll"  kp="18" kv="5" forcerange="-140 140"/>

    <!-- head (small) -->
    <position name="12_head_pan"    joint="head_pan"    kp="10" kv="1" forcerange="-15 15"/>
    <position name="13_head_tilt"   joint="head_tilt"   kp="10" kv="1" forcerange="-15 15"/>

    <!-- right arm (medium) -->
    <position name="14_r_sho_pitch" joint="r_sho_pitch" kp="14" kv="3" forcerange="-70 70"/>
    <position name="15_r_sho_roll"  joint="r_sho_roll"  kp="14" kv="3" forcerange="-70 70"/>
    <position name="16_r_el_pitch"  joint="r_el_pitch"  kp="12" kv="3" forcerange="-60 60"/>
    <position name="17_r_el_yaw"    joint="r_el_yaw"    kp="12" kv="3" forcerange="-60 60"/>
    <position name="18_r_gripper"   joint="r_gripper"   kp="10" kv="2" forcerange="-25 25"/>

    <!-- left arm -->
    <position name="19_l_sho_pitch" joint="l_sho_pitch" kp="14" kv="3" forcerange="-70 70"/>
    <position name="20_l_sho_roll"  joint="l_sho_roll"  kp="14" kv="3" forcerange="-70 70"/>
    <position name="21_l_el_pitch"  joint="l_el_pitch"  kp="12" kv="3" forcerange="-60 60"/>
    <position name="22_l_el_yaw"    joint="l_el_yaw"    kp="12" kv="3" forcerange="-60 60"/>
    <position name="23_l_gripper"   joint="l_gripper"   kp="10" kv="2" forcerange="-25 25"/>
  </actuator>

</mujoco>