<mujoco model="robotic_arm_reach">
    <compiler angle="degree" coordinate="local" />
    <option timestep="0.01" gravity="0 0 -9.81"/>

    <worldbody>
        <!-- Ground -->
        <geom name="floor" type="plane" size="1 1 0.1" rgba="0.8 0.9 0.8 1"/>

        <!-- Arm base -->
        <body name="base" pos="0 0 0.02">
            <geom type="cylinder" size="0.03 0.02" rgba="0.4 0.4 0.4 1"/>

            <!-- First link -->
            <body name="link1" pos="0 0 0">
                <joint name="joint1" type="hinge" axis="0 0 1" range="-90 90" damping="0.05"/>
                <!-- from base outward along X axis -->
                <geom type="capsule" fromto="0 0 0 0.2 0 0" size="0.02" rgba="0.2 0.6 0.9 1"/>

                <!-- Second link -->
                <body name="link2" pos="0.2 0 0">
                    <joint name="joint2" type="hinge" axis="0 0 1" range="-90 90" damping="0.05"/>
                    <!-- continues outward along X -->
                    <geom type="capsule" fromto="0 0 0 0.2 0 0" size="0.02" rgba="0.2 0.9 0.4 1"/>

                    <!-- End effector site -->
                    <site name="ee_site" pos="0.2 0 0" size="0.02" rgba="1 0 0 1"/>
                </body>
            </body>
        </body>

        <!-- Target (environment can move it) -->
        <body name="target" pos="0.4 0.0 0.02">
            <geom name="ball" type="sphere" size="0.03" rgba="1 0 0 1"/>
        </body>
    </worldbody>

    <!-- Actuators -->
    <actuator>
        <motor name="motor1" joint="joint1" ctrlrange="-1 1" gear="1"/>
        <motor name="motor2" joint="joint2" ctrlrange="-1 1" gear="1"/>
    </actuator>
</mujoco>
